Workbook

Sheet Notes
A1: Read this first
A3: What this workbook is
A4: A sales dashboard and a monthly revenue forecast built on the UCI Online Retail II transaction file.
A5: The Dashboard and Forecast sheets contain live formulas, not pasted values. Open it and press F9 - the numbers rebuild from the Data sheet.
A6: Authoritative numbers are produced by analysis/run_analysis.py in the repository. This workbook reproduces them independently with LINEST.
A8: Honest note on PivotTables
A9: This file contains NO PivotTables. openpyxl cannot write a pivotCache or pivotTable part, so claiming one would be false.
A10: The pivot logic - revenue sliced by month, region and product - is implemented with SUMIFS against a tidy fact table on the Data sheet, plus a data-validation dropdown that re-filters the KPI row.
A11: For the reader's purpose this is equivalent: it produces the same cross-tab, it recalculates live when the source data changes, and unlike a PivotTable it does not need a manual refresh.
A13: Data grain
A14: The Data sheet holds 845 aggregated rows at month x region x product-group grain.
A15: The underlying transaction file has 1,067,371 raw line items. Putting those in a workbook would produce a several-hundred-megabyte file and make every SUMIFS crawl, so the line level lives in the Python pipeline and the workbook carries the aggregate.
... A28: Dropped-row ledger
A29: Step | B29: Rows dropped | C29: Rows remaining | D29: Why
A30: cross_sheet_overlap | B30: 22523 | C30: 1044848 | D30: Sheets 'Year 2009-2010' and 'Year 2010-2011' both cover 2010-12-01 to 2010-12-09. Kept the sheet-1 copy, dropped the sheet-2 duplicate.
A31: exact_duplicate_lines | B31: 11814 | C31: 1033034 | D31: Identical Invoice+StockCode+Quantity+Price+timestamp+Country rows. Same line recorded twice; keeping both would double-count revenue.
A32: credit_notes | B32: 19104 | C32: 1013930 | D32: Invoice numbers starting with 'C' are cancellations/returns with negative quantities. Excluded so the series measures gross sales.
A33: admin_stock_codes | B33: 4631 | C33: 1009299 | D33: Postage (POST/DOT), manual adjustments (M/ADJUST), bank charges, samples, Amazon fees, gift vouchers and TEST rows are not product sales.
A34: nonpositive_quantity | B34: 3392 | C34: 1005907 | D34: Quantity <= 0 outside the credit-note set: write-offs and stock corrections, not sales.
A35: nonpositive_price | B35: 2571 | C35: 1003336 | D35: Price <= 0 lines produce zero or negative revenue; they are freebies and entry errors, not sales.
A36: truncated_final_month | B36: 24753 | C36: 978583 | D36: The file stops on 2011-12-09, so December 2011 is a part-month and would read as a 58% collapse in a monthly series.
A38: Resume claims checked against the data
A39: Claim | B39: Verdict | C39: What the data says
A40: 15K+ monthly sales records | B40: supported | C40: 40,774 clean records per month (978,583 over 24 months)
A41: across 4 regions | B41: contradicted | C41: 43 countries, no region column
A42: and 12 products | B42: contradicted | C42: 4,893 distinct stock codes; the top 12 are only 8.36% of revenue
A43: Used pivot tables, VLOOKUP, conditional formatting and charts | B43: partially_supported | C43: VLOOKUP, conditional formatting and native charts are in the workbook. There are no PivotTables.
A44: linear regression to forecast next-quarter sales with 93% accuracy | B44: partially_supported | C44: MAPE 5.49% on the held-out quarter (= 94.51% 'accuracy'), RMSE GBP 89,466, R2 0.765 on n=3 months
A45: reducing inventory gaps by 18% | B45: unverifiable | C45: no inventory, stock-out or fulfilment field exists in this dataset

Sheet Data
A1: Month | B1: Region | C1: ProductCode | D1: ProductName | E1: Revenue | F1: Units | G1: Orders | H1: Year | I1: MonthNo
A2: 2009-12 | B2: Ireland (EIRE) | C2: 20725 | D2: LUNCH BAG RED RETROSPOT | E2: 145 | F2: 100 | G2: 1 | H2: 2009 | I2: 12
A3: 2009-12 | B3: Ireland (EIRE) | C3: 22086 | D3: PAPER CHAIN KIT 50'S CHRISTMAS | E3: 17.7 | F3: 6 | G3: 1 | H3: 2009 | I3: 12
A4: 2009-12 | B4: Ireland (EIRE) | C4: 22197 | D4: SMALL POPCORN HOLDER | E4: 51 | F4: 60 | G4: 2 | H4: 2009 | I4: 12
A5: 2009-12 | B5: Ireland (EIRE) | C5: 79321 | D5: CHILLI LIGHTS | E5: 19.8 | F5: 4 | G5: 1 | H5: 2009 | I5: 12
A6: 2009-12 | B6: Ireland (EIRE) | C6: 84879 | D6: ASSORTED COLOUR BIRD ORNAMENT | E6: 13.52 | F6: 8 | G6: 1 | H6: 2009 | I6: 12
A7: 2009-12 | B7: Ireland (EIRE) | C7: 85099B | D7: JUMBO BAG RED RETROSPOT | E7: 19.5 | F7: 10 | G7: 1 | H7: 2009 | I7: 12
A8: 2009-12 | B8: Ireland (EIRE) | C8: 85123A | D8: WHITE HANGING HEART T-LIGHT HOLDER | E8: 333.3 | F8: 126 | G8: 4 | H8: 2009 | I8: 12
A9: 2009-12 | B9: Ireland (EIRE) | C9: ALL OTHER PRODUCTS | D9: All other products | E9: 18346.67 | F9: 9092 | G9: 18 | H9: 2009 | I9: 12
A10: 2009-12 | B10: Rest of Europe | C10: 20725 | D10: LUNCH BAG RED RETROSPOT | E10: 161.5 | F10: 110 | G10: 2 | H10: 2009 | I10: 12
A11: 2009-12 | B11: Rest of Europe | C11: 22197 | D11: SMALL POPCORN HOLDER | E11: 20.4 | F11: 24 | G11: 2 | H11: 2009 | I11: 12
A12: 2009-12 | B12: Rest of Europe | C12: 47566 | D12: PARTY BUNTING | E12: 23.25 | F12: 5 | G12: 1 | H12: 2009 | I12: 12
A13: 2009-12 | B13: Rest of Europe | C13: 84347 | D13: ROTATING SILVER ANGELS T-LIGHT HLDR | E13: 1008 | F13: 480 | G13: 1 | H13: 2009 | I13: 12
... A846: 2011-11 | B846: United Kingdom | C846: ALL OTHER PRODUCTS | D846: All other products | E846: 1163546.3 | F846: 602880 | G846: 2469 | H846: 2011 | I846: 11

Sheet Lookups
A1: Lookup tables
A2: VLOOKUP targets and the lists that drive the Dashboard dropdown.
E3: Region | G3: Month
A4: ProductCode | B4: ProductName | C4: TotalRevenue | E4: All regions | G4: 2009-12
A5: 22423 | B5: REGENCY CAKESTAND 3 TIER | C5: =SUMIFS(Data!$E$2:$E$846,Data!$C$2:$C$846,$A5) | E5: United Kingdom | G5: 2010-01
A6: 85123A | B6: WHITE HANGING HEART T-LIGHT HOLDER | C6: =SUMIFS(Data!$E$2:$E$846,Data!$C$2:$C$846,$A6) | E6: Ireland (EIRE) | G6: 2010-02
A7: 85099B | B7: JUMBO BAG RED RETROSPOT | C7: =SUMIFS(Data!$E$2:$E$846,Data!$C$2:$C$846,$A7) | E7: Rest of Europe | G7: 2010-03
A8: 47566 | B8: PARTY BUNTING | C8: =SUMIFS(Data!$E$2:$E$846,Data!$C$2:$C$846,$A8) | E8: Rest of World | G8: 2010-04
A9: 84879 | B9: ASSORTED COLOUR BIRD ORNAMENT | C9: =SUMIFS(Data!$E$2:$E$846,Data!$C$2:$C$846,$A9) | G9: 2010-05
A10: 22086 | B10: PAPER CHAIN KIT 50'S CHRISTMAS | C10: =SUMIFS(Data!$E$2:$E$846,Data!$C$2:$C$846,$A10) | G10: 2010-06
A11: 23166 | B11: MEDIUM CERAMIC TOP STORAGE JAR | C11: =SUMIFS(Data!$E$2:$E$846,Data!$C$2:$C$846,$A11) | G11: 2010-07
A12: 79321 | B12: CHILLI LIGHTS | C12: =SUMIFS(Data!$E$2:$E$846,Data!$C$2:$C$846,$A12) | G12: 2010-08
A13: 22386 | B13: JUMBO BAG PINK POLKADOT | C13: =SUMIFS(Data!$E$2:$E$846,Data!$C$2:$C$846,$A13) | G13: 2010-09
A14: 22197 | B14: SMALL POPCORN HOLDER | C14: =SUMIFS(Data!$E$2:$E$846,Data!$C$2:$C$846,$A14) | G14: 2010-10
A15: 20725 | B15: LUNCH BAG RED RETROSPOT | C15: =SUMIFS(Data!$E$2:$E$846,Data!$C$2:$C$846,$A15) | G15: 2010-11
A16: 84347 | B16: ROTATING SILVER ANGELS T-LIGHT HLDR | C16: =SUMIFS(Data!$E$2:$E$846,Data!$C$2:$C$846,$A16) | G16: 2010-12
A17: ALL OTHER PRODUCTS | B17: All other products | C17: =SUMIFS(Data!$E$2:$E$846,Data!$C$2:$C$846,$A17) | G17: 2011-01
G18: 2011-02
G19: 2011-03
G20: 2011-04
G21: 2011-05
G22: 2011-06
G23: 2011-07
G24: 2011-08
G25: 2011-09
G26: 2011-10
G27: 2011-11

Sheet Dashboard
A1: Online Retail II - sales dashboard
A2: Every figure below is a live formula over the Data sheet. Change the region filter and the whole KPI row recalculates.
A4: Region filter | B4: All regions | D4: Total revenue (GBP) | F4: Units sold | H4: Order lines | J4: Peak month revenue | L4: Average month revenue | N4: Peak / trough ratio
D5: =IF($B$4="All regions",SUM(Data!$E$2:$E$846),SUMIFS(Data!$E$2:$E$846,Data!$B$2:$B$846,$B$4)) | F5: =IF($B$4="All regions",SUM(Data!$F$2:$F$846),SUMIFS(Data!$F$2:$F$846,Data!$B$2:$B$846,$B$4)) | H5: =IF($B$4="All regions",SUM(Data!$G$2:$G$846),SUMIFS(Data!$G$2:$G$846,Data!$B$2:$B$846,$B$4)) | J5: =MAX(B10:B33) | L5: =AVERAGE(B10:B33) | N5: =MAX(B10:B33)/MIN(B10:B33)
A8: Revenue by month and region
A9: Month | B9: Total (filtered) | C9: United Kingdom | D9: Ireland (EIRE) | E9: Rest of Europe | F9: Rest of World | G9: MoM growth
A10: 2009-12 | B10: =IF($B$4="All regions",SUMIFS(Data!$E$2:$E$846,Data!$A$2:$A$846,$A10),SUMIFS(Data!$E$2:$E$846,Data!$A$2:$A$846,$A10,Data!$B$2:$B$846,$B$4)) | C10: =SUMIFS(Data!$E$2:$E$846,Data!$A$2:$A$846,$A10,Data!$B$2:$B$846,"United Kingdom") | D10: =SUMIFS(Data!$E$2:$E$846,Data!$A$2:$A$846,$A10,Data!$B$2:$B$846,"Ireland (EIRE)") | E10: =SUMIFS(Data!$E$2:$E$846,Data!$A$2:$A$846,$A10,Data!$B$2:$B$846,"Rest of Europe") | F10: =SUMIFS(Data!$E$2:$E$846,Data!$A$2:$A$846,$A10,Data!$B$2:$B$846,"Rest of World")
A11: 2010-01 | B11: =IF($B$4="All regions",SUMIFS(Data!$E$2:$E$846,Data!$A$2:$A$846,$A11),SUMIFS(Data!$E$2:$E$846,Data!$A$2:$A$846,$A11,Data!$B$2:$B$846,$B$4)) | C11: =SUMIFS(Data!$E$2:$E$846,Data!$A$2:$A$846,$A11,Data!$B$2:$B$846,"United Kingdom") | D11: =SUMIFS(Data!$E$2:$E$846,Data!$A$2:$A$846,$A11,Data!$B$2:$B$846,"Ireland (EIRE)") | E11: =SUMIFS(Data!$E$2:$E$846,Data!$A$2:$A$846,$A11,Data!$B$2:$B$846,"Rest of Europe") | F11: =SUMIFS(Data!$E$2:$E$846,Data!$A$2:$A$846,$A11,Data!$B$2:$B$846,"Rest of World") | G11: =IFERROR(B11/B10-1,"")
A12: 2010-02 | B12: =IF($B$4="All regions",SUMIFS(Data!$E$2:$E$846,Data!$A$2:$A$846,$A12),SUMIFS(Data!$E$2:$E$846,Data!$A$2:$A$846,$A12,Data!$B$2:$B$846,$B$4)) | C12: =SUMIFS(Data!$E$2:$E$846,Data!$A$2:$A$846,$A12,Data!$B$2:$B$846,"United Kingdom") | D12: =SUMIFS(Data!$E$2:$E$846,Data!$A$2:$A$846,$A12,Data!$B$2:$B$846,"Ireland (EIRE)") | E12: =SUMIFS(Data!$E$2:$E$846,Data!$A$2:$A$846,$A12,Data!$B$2:$B$846,"Rest of Europe") | F12: =SUMIFS(Data!$E$2:$E$846,Data!$A$2:$A$846,$A12,Data!$B$2:$B$846,"Rest of World") | G12: =IFERROR(B12/B11-1,"")
A13: 2010-03 | B13: =IF($B$4="All regions",SUMIFS(Data!$E$2:$E$846,Data!$A$2:$A$846,$A13),SUMIFS(Data!$E$2:$E$846,Data!$A$2:$A$846,$A13,Data!$B$2:$B$846,$B$4)) | C13: =SUMIFS(Data!$E$2:$E$846,Data!$A$2:$A$846,$A13,Data!$B$2:$B$846,"United Kingdom") | D13: =SUMIFS(Data!$E$2:$E$846,Data!$A$2:$A$846,$A13,Data!$B$2:$B$846,"Ireland (EIRE)") | E13: =SUMIFS(Data!$E$2:$E$846,Data!$A$2:$A$846,$A13,Data!$B$2:$B$846,"Rest of Europe") | F13: =SUMIFS(Data!$E$2:$E$846,Data!$A$2:$A$846,$A13,Data!$B$2:$B$846,"Rest of World") | G13: =IFERROR(B13/B12-1,"")
A14: 2010-04 | B14: =IF($B$4="All regions",SUMIFS(Data!$E$2:$E$846,Data!$A$2:$A$846,$A14),SUMIFS(Data!$E$2:$E$846,Data!$A$2:$A$846,$A14,Data!$B$2:$B$846,$B$4)) | C14: =SUMIFS(Data!$E$2:$E$846,Data!$A$2:$A$846,$A14,Data!$B$2:$B$846,"United Kingdom") | D14: =SUMIFS(Data!$E$2:$E$846,Data!$A$2:$A$846,$A14,Data!$B$2:$B$846,"Ireland (EIRE)") | E14: =SUMIFS(Data!$E$2:$E$846,Data!$A$2:$A$846,$A14,Data!$B$2:$B$846,"Rest of Europe") | F14: =SUMIFS(Data!$E$2:$E$846,Data!$A$2:$A$846,$A14,Data!$B$2:$B$846,"Rest of World") | G14: =IFERROR(B14/B13-1,"")
A15: 2010-05 | B15: =IF($B$4="All regions",SUMIFS(Data!$E$2:$E$846,Data!$A$2:$A$846,$A15),SUMIFS(Data!$E$2:$E$846,Data!$A$2:$A$846,$A15,Data!$B$2:$B$846,$B$4)) | C15: =SUMIFS(Data!$E$2:$E$846,Data!$A$2:$A$846,$A15,Data!$B$2:$B$846,"United Kingdom") | D15: =SUMIFS(Data!$E$2:$E$846,Data!$A$2:$A$846,$A15,Data!$B$2:$B$846,"Ireland (EIRE)") | E15: =SUMIFS(Data!$E$2:$E$846,Data!$A$2:$A$846,$A15,Data!$B$2:$B$846,"Rest of Europe") | F15: =SUMIFS(Data!$E$2:$E$846,Data!$A$2:$A$846,$A15,Data!$B$2:$B$846,"Rest of World") | G15: =IFERROR(B15/B14-1,"")
A16: 2010-06 | B16: =IF($B$4="All regions",SUMIFS(Data!$E$2:$E$846,Data!$A$2:$A$846,$A16),SUMIFS(Data!$E$2:$E$846,Data!$A$2:$A$846,$A16,Data!$B$2:$B$846,$B$4)) | C16: =SUMIFS(Data!$E$2:$E$846,Data!$A$2:$A$846,$A16,Data!$B$2:$B$846,"United Kingdom") | D16: =SUMIFS(Data!$E$2:$E$846,Data!$A$2:$A$846,$A16,Data!$B$2:$B$846,"Ireland (EIRE)") | E16: =SUMIFS(Data!$E$2:$E$846,Data!$A$2:$A$846,$A16,Data!$B$2:$B$846,"Rest of Europe") | F16: =SUMIFS(Data!$E$2:$E$846,Data!$A$2:$A$846,$A16,Data!$B$2:$B$846,"Rest of World") | G16: =IFERROR(B16/B15-1,"")
A17: 2010-07 | B17: =IF($B$4="All regions",SUMIFS(Data!$E$2:$E$846,Data!$A$2:$A$846,$A17),SUMIFS(Data!$E$2:$E$846,Data!$A$2:$A$846,$A17,Data!$B$2:$B$846,$B$4)) | C17: =SUMIFS(Data!$E$2:$E$846,Data!$A$2:$A$846,$A17,Data!$B$2:$B$846,"United Kingdom") | D17: =SUMIFS(Data!$E$2:$E$846,Data!$A$2:$A$846,$A17,Data!$B$2:$B$846,"Ireland (EIRE)") | E17: =SUMIFS(Data!$E$2:$E$846,Data!$A$2:$A$846,$A17,Data!$B$2:$B$846,"Rest of Europe") | F17: =SUMIFS(Data!$E$2:$E$846,Data!$A$2:$A$846,$A17,Data!$B$2:$B$846,"Rest of World") | G17: =IFERROR(B17/B16-1,"")
A18: 2010-08 | B18: =IF($B$4="All regions",SUMIFS(Data!$E$2:$E$846,Data!$A$2:$A$846,$A18),SUMIFS(Data!$E$2:$E$846,Data!$A$2:$A$846,$A18,Data!$B$2:$B$846,$B$4)) | C18: =SUMIFS(Data!$E$2:$E$846,Data!$A$2:$A$846,$A18,Data!$B$2:$B$846,"United Kingdom") | D18: =SUMIFS(Data!$E$2:$E$846,Data!$A$2:$A$846,$A18,Data!$B$2:$B$846,"Ireland (EIRE)") | E18: =SUMIFS(Data!$E$2:$E$846,Data!$A$2:$A$846,$A18,Data!$B$2:$B$846,"Rest of Europe") | F18: =SUMIFS(Data!$E$2:$E$846,Data!$A$2:$A$846,$A18,Data!$B$2:$B$846,"Rest of World") | G18: =IFERROR(B18/B17-1,"")
A19: 2010-09 | B19: =IF($B$4="All regions",SUMIFS(Data!$E$2:$E$846,Data!$A$2:$A$846,$A19),SUMIFS(Data!$E$2:$E$846,Data!$A$2:$A$846,$A19,Data!$B$2:$B$846,$B$4)) | C19: =SUMIFS(Data!$E$2:$E$846,Data!$A$2:$A$846,$A19,Data!$B$2:$B$846,"United Kingdom") | D19: =SUMIFS(Data!$E$2:$E$846,Data!$A$2:$A$846,$A19,Data!$B$2:$B$846,"Ireland (EIRE)") | E19: =SUMIFS(Data!$E$2:$E$846,Data!$A$2:$A$846,$A19,Data!$B$2:$B$846,"Rest of Europe") | F19: =SUMIFS(Data!$E$2:$E$846,Data!$A$2:$A$846,$A19,Data!$B$2:$B$846,"Rest of World") | G19: =IFERROR(B19/B18-1,"")
A20: 2010-10 | B20: =IF($B$4="All regions",SUMIFS(Data!$E$2:$E$846,Data!$A$2:$A$846,$A20),SUMIFS(Data!$E$2:$E$846,Data!$A$2:$A$846,$A20,Data!$B$2:$B$846,$B$4)) | C20: =SUMIFS(Data!$E$2:$E$846,Data!$A$2:$A$846,$A20,Data!$B$2:$B$846,"United Kingdom") | D20: =SUMIFS(Data!$E$2:$E$846,Data!$A$2:$A$846,$A20,Data!$B$2:$B$846,"Ireland (EIRE)") | E20: =SUMIFS(Data!$E$2:$E$846,Data!$A$2:$A$846,$A20,Data!$B$2:$B$846,"Rest of Europe") | F20: =SUMIFS(Data!$E$2:$E$846,Data!$A$2:$A$846,$A20,Data!$B$2:$B$846,"Rest of World") | G20: =IFERROR(B20/B19-1,"")
A21: 2010-11 | B21: =IF($B$4="All regions",SUMIFS(Data!$E$2:$E$846,Data!$A$2:$A$846,$A21),SUMIFS(Data!$E$2:$E$846,Data!$A$2:$A$846,$A21,Data!$B$2:$B$846,$B$4)) | C21: =SUMIFS(Data!$E$2:$E$846,Data!$A$2:$A$846,$A21,Data!$B$2:$B$846,"United Kingdom") | D21: =SUMIFS(Data!$E$2:$E$846,Data!$A$2:$A$846,$A21,Data!$B$2:$B$846,"Ireland (EIRE)") | E21: =SUMIFS(Data!$E$2:$E$846,Data!$A$2:$A$846,$A21,Data!$B$2:$B$846,"Rest of Europe") | F21: =SUMIFS(Data!$E$2:$E$846,Data!$A$2:$A$846,$A21,Data!$B$2:$B$846,"Rest of World") | G21: =IFERROR(B21/B20-1,"")
A22: 2010-12 | B22: =IF($B$4="All regions",SUMIFS(Data!$E$2:$E$846,Data!$A$2:$A$846,$A22),SUMIFS(Data!$E$2:$E$846,Data!$A$2:$A$846,$A22,Data!$B$2:$B$846,$B$4)) | C22: =SUMIFS(Data!$E$2:$E$846,Data!$A$2:$A$846,$A22,Data!$B$2:$B$846,"United Kingdom") | D22: =SUMIFS(Data!$E$2:$E$846,Data!$A$2:$A$846,$A22,Data!$B$2:$B$846,"Ireland (EIRE)") | E22: =SUMIFS(Data!$E$2:$E$846,Data!$A$2:$A$846,$A22,Data!$B$2:$B$846,"Rest of Europe") | F22: =SUMIFS(Data!$E$2:$E$846,Data!$A$2:$A$846,$A22,Data!$B$2:$B$846,"Rest of World") | G22: =IFERROR(B22/B21-1,"")
... A33: 2011-11 | B33: =IF($B$4="All regions",SUMIFS(Data!$E$2:$E$846,Data!$A$2:$A$846,$A33),SUMIFS(Data!$E$2:$E$846,Data!$A$2:$A$846,$A33,Data!$B$2:$B$846,$B$4)) | C33: =SUMIFS(Data!$E$2:$E$846,Data!$A$2:$A$846,$A33,Data!$B$2:$B$846,"United Kingdom") | D33: =SUMIFS(Data!$E$2:$E$846,Data!$A$2:$A$846,$A33,Data!$B$2:$B$846,"Ireland (EIRE)") | E33: =SUMIFS(Data!$E$2:$E$846,Data!$A$2:$A$846,$A33,Data!$B$2:$B$846,"Rest of Europe") | F33: =SUMIFS(Data!$E$2:$E$846,Data!$A$2:$A$846,$A33,Data!$B$2:$B$846,"Rest of World") | G33: =IFERROR(B33/B32-1,"")
A35: Top 12 products by revenue (of 4,893 distinct stock codes)
A36: ProductCode | B36: Product name (VLOOKUP) | C36: Revenue | D36: Units | E36: Share of total | F36: Revenue per unit
A37: 22423 | B37: =VLOOKUP($A37,Lookups!$A:$B,2,FALSE) | C37: =SUMIFS(Data!$E$2:$E$846,Data!$C$2:$C$846,$A37) | D37: =SUMIFS(Data!$F$2:$F$846,Data!$C$2:$C$846,$A37) | E37: =C37/SUM(Data!$E$2:$E$846) | F37: =IFERROR(C37/D37,"")
A38: 85123A | B38: =VLOOKUP($A38,Lookups!$A:$B,2,FALSE) | C38: =SUMIFS(Data!$E$2:$E$846,Data!$C$2:$C$846,$A38) | D38: =SUMIFS(Data!$F$2:$F$846,Data!$C$2:$C$846,$A38) | E38: =C38/SUM(Data!$E$2:$E$846) | F38: =IFERROR(C38/D38,"")
A39: 85099B | B39: =VLOOKUP($A39,Lookups!$A:$B,2,FALSE) | C39: =SUMIFS(Data!$E$2:$E$846,Data!$C$2:$C$846,$A39) | D39: =SUMIFS(Data!$F$2:$F$846,Data!$C$2:$C$846,$A39) | E39: =C39/SUM(Data!$E$2:$E$846) | F39: =IFERROR(C39/D39,"")
A40: 47566 | B40: =VLOOKUP($A40,Lookups!$A:$B,2,FALSE) | C40: =SUMIFS(Data!$E$2:$E$846,Data!$C$2:$C$846,$A40) | D40: =SUMIFS(Data!$F$2:$F$846,Data!$C$2:$C$846,$A40) | E40: =C40/SUM(Data!$E$2:$E$846) | F40: =IFERROR(C40/D40,"")
A41: 84879 | B41: =VLOOKUP($A41,Lookups!$A:$B,2,FALSE) | C41: =SUMIFS(Data!$E$2:$E$846,Data!$C$2:$C$846,$A41) | D41: =SUMIFS(Data!$F$2:$F$846,Data!$C$2:$C$846,$A41) | E41: =C41/SUM(Data!$E$2:$E$846) | F41: =IFERROR(C41/D41,"")
A42: 22086 | B42: =VLOOKUP($A42,Lookups!$A:$B,2,FALSE) | C42: =SUMIFS(Data!$E$2:$E$846,Data!$C$2:$C$846,$A42) | D42: =SUMIFS(Data!$F$2:$F$846,Data!$C$2:$C$846,$A42) | E42: =C42/SUM(Data!$E$2:$E$846) | F42: =IFERROR(C42/D42,"")
A43: 23166 | B43: =VLOOKUP($A43,Lookups!$A:$B,2,FALSE) | C43: =SUMIFS(Data!$E$2:$E$846,Data!$C$2:$C$846,$A43) | D43: =SUMIFS(Data!$F$2:$F$846,Data!$C$2:$C$846,$A43) | E43: =C43/SUM(Data!$E$2:$E$846) | F43: =IFERROR(C43/D43,"")
A44: 79321 | B44: =VLOOKUP($A44,Lookups!$A:$B,2,FALSE) | C44: =SUMIFS(Data!$E$2:$E$846,Data!$C$2:$C$846,$A44) | D44: =SUMIFS(Data!$F$2:$F$846,Data!$C$2:$C$846,$A44) | E44: =C44/SUM(Data!$E$2:$E$846) | F44: =IFERROR(C44/D44,"")
A45: 22386 | B45: =VLOOKUP($A45,Lookups!$A:$B,2,FALSE) | C45: =SUMIFS(Data!$E$2:$E$846,Data!$C$2:$C$846,$A45) | D45: =SUMIFS(Data!$F$2:$F$846,Data!$C$2:$C$846,$A45) | E45: =C45/SUM(Data!$E$2:$E$846) | F45: =IFERROR(C45/D45,"")
A46: 22197 | B46: =VLOOKUP($A46,Lookups!$A:$B,2,FALSE) | C46: =SUMIFS(Data!$E$2:$E$846,Data!$C$2:$C$846,$A46) | D46: =SUMIFS(Data!$F$2:$F$846,Data!$C$2:$C$846,$A46) | E46: =C46/SUM(Data!$E$2:$E$846) | F46: =IFERROR(C46/D46,"")
A47: 20725 | B47: =VLOOKUP($A47,Lookups!$A:$B,2,FALSE) | C47: =SUMIFS(Data!$E$2:$E$846,Data!$C$2:$C$846,$A47) | D47: =SUMIFS(Data!$F$2:$F$846,Data!$C$2:$C$846,$A47) | E47: =C47/SUM(Data!$E$2:$E$846) | F47: =IFERROR(C47/D47,"")
A48: 84347 | B48: =VLOOKUP($A48,Lookups!$A:$B,2,FALSE) | C48: =SUMIFS(Data!$E$2:$E$846,Data!$C$2:$C$846,$A48) | D48: =SUMIFS(Data!$F$2:$F$846,Data!$C$2:$C$846,$A48) | E48: =C48/SUM(Data!$E$2:$E$846) | F48: =IFERROR(C48/D48,"")

Sheet Forecast
A1: Forecast - trend + month-of-year regression
A2: LINEST fits the model on the first 21 months only. The last 3 months are held out; the workbook never sees them during fitting.
AI4: Coefficients (Excel LINEST, training rows 6-26). LINEST returns coefficients in reverse column order with the intercept last; these cells unpick that. The forecast column uses TREND and does not depend on this block.
A5: Month | B5: t | C5: Actual | D5: Set | E5: m02 | F5: m03 | G5: m04 | H5: m05 | I5: m06 | J5: m07 | K5: m08 | L5: m09 | M5: m10 | N5: m11 | O5: m12 | P5: Regression | Q5: Seasonal naive | R5: APE reg | S5: APE snaive | U5: t (design) | V5: x02 | W5: x03 | X5: x04 | Y5: x05 | Z5: x06 | AA5: x07 | AB5: x08 | AC5: x09 | AD5: x10 | AE5: x11 | AF5: x12
A6: 2009-12 | B6: 0 | C6: 797901.16 | D6: train | E6: 0 | F6: 0 | G6: 0 | H6: 0 | I6: 0 | J6: 0 | K6: 0 | L6: 0 | M6: 0 | N6: 0 | O6: 1 | P6: =TREND($C$6:$C$26,$U$6:$AF$26,$U6:$AF6) | R6: =ABS((C6-P6)/C6) | S6: =IF(Q6="","",ABS((C6-Q6)/C6)) | U6: 0 | V6: 0 | W6: 0 | X6: 0 | Y6: 0 | Z6: 0 | AA6: 0 | AB6: 0 | AC6: 0 | AD6: 0 | AE6: 0 | AF6: 1 | AI6: Intercept | AJ6: =INDEX(LINEST($C$6:$C$26,$U$6:$AF$26,TRUE,FALSE),1,13)
A7: 2010-01 | B7: 1 | C7: 612297.42 | D7: train | E7: 0 | F7: 0 | G7: 0 | H7: 0 | I7: 0 | J7: 0 | K7: 0 | L7: 0 | M7: 0 | N7: 0 | O7: 0 | P7: =TREND($C$6:$C$26,$U$6:$AF$26,$U7:$AF7) | R7: =ABS((C7-P7)/C7) | S7: =IF(Q7="","",ABS((C7-Q7)/C7)) | U7: 1 | V7: 0 | W7: 0 | X7: 0 | Y7: 0 | Z7: 0 | AA7: 0 | AB7: 0 | AC7: 0 | AD7: 0 | AE7: 0 | AF7: 0 | AI7: Trend (per month) | AJ7: =INDEX(LINEST($C$6:$C$26,$U$6:$AF$26,TRUE,FALSE),1,12)
A8: 2010-02 | B8: 2 | C8: 537909.67 | D8: train | E8: 1 | F8: 0 | G8: 0 | H8: 0 | I8: 0 | J8: 0 | K8: 0 | L8: 0 | M8: 0 | N8: 0 | O8: 0 | P8: =TREND($C$6:$C$26,$U$6:$AF$26,$U8:$AF8) | R8: =ABS((C8-P8)/C8) | S8: =IF(Q8="","",ABS((C8-Q8)/C8)) | U8: 2 | V8: 1 | W8: 0 | X8: 0 | Y8: 0 | Z8: 0 | AA8: 0 | AB8: 0 | AC8: 0 | AD8: 0 | AE8: 0 | AF8: 0 | AI8: Month 02 vs Jan | AJ8: =INDEX(LINEST($C$6:$C$26,$U$6:$AF$26,TRUE,FALSE),1,11)
A9: 2010-03 | B9: 3 | C9: 761705.98 | D9: train | E9: 0 | F9: 1 | G9: 0 | H9: 0 | I9: 0 | J9: 0 | K9: 0 | L9: 0 | M9: 0 | N9: 0 | O9: 0 | P9: =TREND($C$6:$C$26,$U$6:$AF$26,$U9:$AF9) | R9: =ABS((C9-P9)/C9) | S9: =IF(Q9="","",ABS((C9-Q9)/C9)) | U9: 3 | V9: 0 | W9: 1 | X9: 0 | Y9: 0 | Z9: 0 | AA9: 0 | AB9: 0 | AC9: 0 | AD9: 0 | AE9: 0 | AF9: 0 | AI9: Month 03 vs Jan | AJ9: =INDEX(LINEST($C$6:$C$26,$U$6:$AF$26,TRUE,FALSE),1,10)
A10: 2010-04 | B10: 4 | C10: 646340.93 | D10: train | E10: 0 | F10: 0 | G10: 1 | H10: 0 | I10: 0 | J10: 0 | K10: 0 | L10: 0 | M10: 0 | N10: 0 | O10: 0 | P10: =TREND($C$6:$C$26,$U$6:$AF$26,$U10:$AF10) | R10: =ABS((C10-P10)/C10) | S10: =IF(Q10="","",ABS((C10-Q10)/C10)) | U10: 4 | V10: 0 | W10: 0 | X10: 1 | Y10: 0 | Z10: 0 | AA10: 0 | AB10: 0 | AC10: 0 | AD10: 0 | AE10: 0 | AF10: 0 | AI10: Month 04 vs Jan | AJ10: =INDEX(LINEST($C$6:$C$26,$U$6:$AF$26,TRUE,FALSE),1,9)
A11: 2010-05 | B11: 5 | C11: 643492.03 | D11: train | E11: 0 | F11: 0 | G11: 0 | H11: 1 | I11: 0 | J11: 0 | K11: 0 | L11: 0 | M11: 0 | N11: 0 | O11: 0 | P11: =TREND($C$6:$C$26,$U$6:$AF$26,$U11:$AF11) | R11: =ABS((C11-P11)/C11) | S11: =IF(Q11="","",ABS((C11-Q11)/C11)) | U11: 5 | V11: 0 | W11: 0 | X11: 0 | Y11: 1 | Z11: 0 | AA11: 0 | AB11: 0 | AC11: 0 | AD11: 0 | AE11: 0 | AF11: 0 | AI11: Month 05 vs Jan | AJ11: =INDEX(LINEST($C$6:$C$26,$U$6:$AF$26,TRUE,FALSE),1,8)
A12: 2010-06 | B12: 6 | C12: 696583.19 | D12: train | E12: 0 | F12: 0 | G12: 0 | H12: 0 | I12: 1 | J12: 0 | K12: 0 | L12: 0 | M12: 0 | N12: 0 | O12: 0 | P12: =TREND($C$6:$C$26,$U$6:$AF$26,$U12:$AF12) | R12: =ABS((C12-P12)/C12) | S12: =IF(Q12="","",ABS((C12-Q12)/C12)) | U12: 6 | V12: 0 | W12: 0 | X12: 0 | Y12: 0 | Z12: 1 | AA12: 0 | AB12: 0 | AC12: 0 | AD12: 0 | AE12: 0 | AF12: 0 | AI12: Month 06 vs Jan | AJ12: =INDEX(LINEST($C$6:$C$26,$U$6:$AF$26,TRUE,FALSE),1,7)
A13: 2010-07 | B13: 7 | C13: 632994.32 | D13: train | E13: 0 | F13: 0 | G13: 0 | H13: 0 | I13: 0 | J13: 1 | K13: 0 | L13: 0 | M13: 0 | N13: 0 | O13: 0 | P13: =TREND($C$6:$C$26,$U$6:$AF$26,$U13:$AF13) | R13: =ABS((C13-P13)/C13) | S13: =IF(Q13="","",ABS((C13-Q13)/C13)) | U13: 7 | V13: 0 | W13: 0 | X13: 0 | Y13: 0 | Z13: 0 | AA13: 1 | AB13: 0 | AC13: 0 | AD13: 0 | AE13: 0 | AF13: 0 | AI13: Month 07 vs Jan | AJ13: =INDEX(LINEST($C$6:$C$26,$U$6:$AF$26,TRUE,FALSE),1,6)
A14: 2010-08 | B14: 8 | C14: 674037.72 | D14: train | E14: 0 | F14: 0 | G14: 0 | H14: 0 | I14: 0 | J14: 0 | K14: 1 | L14: 0 | M14: 0 | N14: 0 | O14: 0 | P14: =TREND($C$6:$C$26,$U$6:$AF$26,$U14:$AF14) | R14: =ABS((C14-P14)/C14) | S14: =IF(Q14="","",ABS((C14-Q14)/C14)) | U14: 8 | V14: 0 | W14: 0 | X14: 0 | Y14: 0 | Z14: 0 | AA14: 0 | AB14: 1 | AC14: 0 | AD14: 0 | AE14: 0 | AF14: 0 | AI14: Month 08 vs Jan | AJ14: =INDEX(LINEST($C$6:$C$26,$U$6:$AF$26,TRUE,FALSE),1,5)
A15: 2010-09 | B15: 9 | C15: 869243.12 | D15: train | E15: 0 | F15: 0 | G15: 0 | H15: 0 | I15: 0 | J15: 0 | K15: 0 | L15: 1 | M15: 0 | N15: 0 | O15: 0 | P15: =TREND($C$6:$C$26,$U$6:$AF$26,$U15:$AF15) | R15: =ABS((C15-P15)/C15) | S15: =IF(Q15="","",ABS((C15-Q15)/C15)) | U15: 9 | V15: 0 | W15: 0 | X15: 0 | Y15: 0 | Z15: 0 | AA15: 0 | AB15: 0 | AC15: 1 | AD15: 0 | AE15: 0 | AF15: 0 | AI15: Month 09 vs Jan | AJ15: =INDEX(LINEST($C$6:$C$26,$U$6:$AF$26,TRUE,FALSE),1,4)
A16: 2010-10 | B16: 10 | C16: 1094421.2 | D16: train | E16: 0 | F16: 0 | G16: 0 | H16: 0 | I16: 0 | J16: 0 | K16: 0 | L16: 0 | M16: 1 | N16: 0 | O16: 0 | P16: =TREND($C$6:$C$26,$U$6:$AF$26,$U16:$AF16) | R16: =ABS((C16-P16)/C16) | S16: =IF(Q16="","",ABS((C16-Q16)/C16)) | U16: 10 | V16: 0 | W16: 0 | X16: 0 | Y16: 0 | Z16: 0 | AA16: 0 | AB16: 0 | AC16: 0 | AD16: 1 | AE16: 0 | AF16: 0 | AI16: Month 10 vs Jan | AJ16: =INDEX(LINEST($C$6:$C$26,$U$6:$AF$26,TRUE,FALSE),1,3)
A17: 2010-11 | B17: 11 | C17: 1429700.8 | D17: train | E17: 0 | F17: 0 | G17: 0 | H17: 0 | I17: 0 | J17: 0 | K17: 0 | L17: 0 | M17: 0 | N17: 1 | O17: 0 | P17: =TREND($C$6:$C$26,$U$6:$AF$26,$U17:$AF17) | R17: =ABS((C17-P17)/C17) | S17: =IF(Q17="","",ABS((C17-Q17)/C17)) | U17: 11 | V17: 0 | W17: 0 | X17: 0 | Y17: 0 | Z17: 0 | AA17: 0 | AB17: 0 | AC17: 0 | AD17: 0 | AE17: 1 | AF17: 0 | AI17: Month 11 vs Jan | AJ17: =INDEX(LINEST($C$6:$C$26,$U$6:$AF$26,TRUE,FALSE),1,2)
A18: 2010-12 | B18: 12 | C18: 775638.36 | D18: train | E18: 0 | F18: 0 | G18: 0 | H18: 0 | I18: 0 | J18: 0 | K18: 0 | L18: 0 | M18: 0 | N18: 0 | O18: 1 | P18: =TREND($C$6:$C$26,$U$6:$AF$26,$U18:$AF18) | Q18: =C6 | R18: =ABS((C18-P18)/C18) | S18: =IF(Q18="","",ABS((C18-Q18)/C18)) | U18: 12 | V18: 0 | W18: 0 | X18: 0 | Y18: 0 | Z18: 0 | AA18: 0 | AB18: 0 | AC18: 0 | AD18: 0 | AE18: 0 | AF18: 1 | AI18: Month 12 vs Jan | AJ18: =INDEX(LINEST($C$6:$C$26,$U$6:$AF$26,TRUE,FALSE),1,1)
A19: 2011-01 | B19: 13 | C19: 670380.24 | D19: train | E19: 0 | F19: 0 | G19: 0 | H19: 0 | I19: 0 | J19: 0 | K19: 0 | L19: 0 | M19: 0 | N19: 0 | O19: 0 | P19: =TREND($C$6:$C$26,$U$6:$AF$26,$U19:$AF19) | Q19: =C7 | R19: =ABS((C19-P19)/C19) | S19: =IF(Q19="","",ABS((C19-Q19)/C19)) | U19: 13 | V19: 0 | W19: 0 | X19: 0 | Y19: 0 | Z19: 0 | AA19: 0 | AB19: 0 | AC19: 0 | AD19: 0 | AE19: 0 | AF19: 0
A20: 2011-02 | B20: 14 | C20: 507799.87 | D20: train | E20: 1 | F20: 0 | G20: 0 | H20: 0 | I20: 0 | J20: 0 | K20: 0 | L20: 0 | M20: 0 | N20: 0 | O20: 0 | P20: =TREND($C$6:$C$26,$U$6:$AF$26,$U20:$AF20) | Q20: =C8 | R20: =ABS((C20-P20)/C20) | S20: =IF(Q20="","",ABS((C20-Q20)/C20)) | U20: 14 | V20: 1 | W20: 0 | X20: 0 | Y20: 0 | Z20: 0 | AA20: 0 | AB20: 0 | AC20: 0 | AD20: 0 | AE20: 0 | AF20: 0 | AI20: Holdout metrics (3 months, rows 27-29)
A21: 2011-03 | B21: 15 | C21: 689833.51 | D21: train | E21: 0 | F21: 1 | G21: 0 | H21: 0 | I21: 0 | J21: 0 | K21: 0 | L21: 0 | M21: 0 | N21: 0 | O21: 0 | P21: =TREND($C$6:$C$26,$U$6:$AF$26,$U21:$AF21) | Q21: =C9 | R21: =ABS((C21-P21)/C21) | S21: =IF(Q21="","",ABS((C21-Q21)/C21)) | U21: 15 | V21: 0 | W21: 1 | X21: 0 | Y21: 0 | Z21: 0 | AA21: 0 | AB21: 0 | AC21: 0 | AD21: 0 | AE21: 0 | AF21: 0 | AI21: MAPE - regression | AJ21: =AVERAGE(R27:R29)
A22: 2011-04 | B22: 16 | C22: 515377.99 | D22: train | E22: 0 | F22: 0 | G22: 1 | H22: 0 | I22: 0 | J22: 0 | K22: 0 | L22: 0 | M22: 0 | N22: 0 | O22: 0 | P22: =TREND($C$6:$C$26,$U$6:$AF$26,$U22:$AF22) | Q22: =C10 | R22: =ABS((C22-P22)/C22) | S22: =IF(Q22="","",ABS((C22-Q22)/C22)) | U22: 16 | V22: 0 | W22: 0 | X22: 1 | Y22: 0 | Z22: 0 | AA22: 0 | AB22: 0 | AC22: 0 | AD22: 0 | AE22: 0 | AF22: 0 | AI22: MAPE - seasonal naive | AJ22: =AVERAGE(S27:S29)
A23: 2011-05 | B23: 17 | C23: 739938.15 | D23: train | E23: 0 | F23: 0 | G23: 0 | H23: 1 | I23: 0 | J23: 0 | K23: 0 | L23: 0 | M23: 0 | N23: 0 | O23: 0 | P23: =TREND($C$6:$C$26,$U$6:$AF$26,$U23:$AF23) | Q23: =C11 | R23: =ABS((C23-P23)/C23) | S23: =IF(Q23="","",ABS((C23-Q23)/C23)) | U23: 17 | V23: 0 | W23: 0 | X23: 0 | Y23: 1 | Z23: 0 | AA23: 0 | AB23: 0 | AC23: 0 | AD23: 0 | AE23: 0 | AF23: 0 | AI23: RMSE - regression | AJ23: =SQRT(SUMXMY2(C27:C29,P27:P29)/3)
A24: 2011-06 | B24: 18 | C24: 737558.98 | D24: train | E24: 0 | F24: 0 | G24: 0 | H24: 0 | I24: 1 | J24: 0 | K24: 0 | L24: 0 | M24: 0 | N24: 0 | O24: 0 | P24: =TREND($C$6:$C$26,$U$6:$AF$26,$U24:$AF24) | Q24: =C12 | R24: =ABS((C24-P24)/C24) | S24: =IF(Q24="","",ABS((C24-Q24)/C24)) | U24: 18 | V24: 0 | W24: 0 | X24: 0 | Y24: 0 | Z24: 1 | AA24: 0 | AB24: 0 | AC24: 0 | AD24: 0 | AE24: 0 | AF24: 0 | AI24: RMSE - seasonal naive | AJ24: =SQRT(SUMXMY2(C27:C29,Q27:Q29)/3)
A25: 2011-07 | B25: 19 | C25: 688219.34 | D25: train | E25: 0 | F25: 0 | G25: 0 | H25: 0 | I25: 0 | J25: 1 | K25: 0 | L25: 0 | M25: 0 | N25: 0 | O25: 0 | P25: =TREND($C$6:$C$26,$U$6:$AF$26,$U25:$AF25) | Q25: =C13 | R25: =ABS((C25-P25)/C25) | S25: =IF(Q25="","",ABS((C25-Q25)/C25)) | U25: 19 | V25: 0 | W25: 0 | X25: 0 | Y25: 0 | Z25: 0 | AA25: 1 | AB25: 0 | AC25: 0 | AD25: 0 | AE25: 0 | AF25: 0 | AI25: R2 - regression | AJ25: =1-SUMXMY2(C27:C29,P27:P29)/DEVSQ(C27:C29)
A26: 2011-08 | B26: 20 | C26: 724216.5 | D26: train | E26: 0 | F26: 0 | G26: 0 | H26: 0 | I26: 0 | J26: 0 | K26: 1 | L26: 0 | M26: 0 | N26: 0 | O26: 0 | P26: =TREND($C$6:$C$26,$U$6:$AF$26,$U26:$AF26) | Q26: =C14 | R26: =ABS((C26-P26)/C26) | S26: =IF(Q26="","",ABS((C26-Q26)/C26)) | U26: 20 | V26: 0 | W26: 0 | X26: 0 | Y26: 0 | Z26: 0 | AA26: 0 | AB26: 1 | AC26: 0 | AD26: 0 | AE26: 0 | AF26: 0 | AI26: R2 - seasonal naive | AJ26: =1-SUMXMY2(C27:C29,Q27:Q29)/DEVSQ(C27:C29)
A27: 2011-09 | B27: 21 | C27: 1028320.4 | D27: HOLDOUT | E27: 0 | F27: 0 | G27: 0 | H27: 0 | I27: 0 | J27: 0 | K27: 0 | L27: 1 | M27: 0 | N27: 0 | O27: 0 | P27: =TREND($C$6:$C$26,$U$6:$AF$26,$U27:$AF27) | Q27: =C15 | R27: =ABS((C27-P27)/C27) | S27: =IF(Q27="","",ABS((C27-Q27)/C27)) | U27: 21 | V27: 0 | W27: 0 | X27: 0 | Y27: 0 | Z27: 0 | AA27: 0 | AB27: 0 | AC27: 1 | AD27: 0 | AE27: 0 | AF27: 0 | AI27: In-sample R2 (LINEST) | AJ27: =INDEX(LINEST($C$6:$C$26,$U$6:$AF$26,TRUE,TRUE),3,1)
A28: 2011-10 | B28: 22 | C28: 1103314.2 | D28: HOLDOUT | E28: 0 | F28: 0 | G28: 0 | H28: 0 | I28: 0 | J28: 0 | K28: 0 | L28: 0 | M28: 1 | N28: 0 | O28: 0 | P28: =TREND($C$6:$C$26,$U$6:$AF$26,$U28:$AF28) | Q28: =C16 | R28: =ABS((C28-P28)/C28) | S28: =IF(Q28="","",ABS((C28-Q28)/C28)) | U28: 22 | V28: 0 | W28: 0 | X28: 0 | Y28: 0 | Z28: 0 | AA28: 0 | AB28: 0 | AC28: 0 | AD28: 1 | AE28: 0 | AF28: 0
A29: 2011-11 | B29: 23 | C29: 1451579 | D29: HOLDOUT | E29: 0 | F29: 0 | G29: 0 | H29: 0 | I29: 0 | J29: 0 | K29: 0 | L29: 0 | M29: 0 | N29: 1 | O29: 0 | P29: =TREND($C$6:$C$26,$U$6:$AF$26,$U29:$AF29) | Q29: =C17 | R29: =ABS((C29-P29)/C29) | S29: =IF(Q29="","",ABS((C29-Q29)/C29)) | U29: 23 | V29: 0 | W29: 0 | X29: 0 | Y29: 0 | Z29: 0 | AA29: 0 | AB29: 0 | AC29: 0 | AD29: 0 | AE29: 1 | AF29: 0
AI30: Cross-check - values computed in Python by run_analysis.py (these two blocks must agree)
AI31: MAPE regression (%) | AJ31: 5.493
AI32: MAPE seasonal naive (%) | AJ32: 5.9276
AI33: RMSE regression | AJ33: 89466.252
AI34: RMSE seasonal naive | AJ34: 92849.908
AI35: R2 regression | AJ35: 0.7646
AI36: R2 seasonal naive | AJ36: 0.7465
AI37: Rolling-origin MAPE regression (%) | AJ37: 6.8259
AI38: Rolling-origin MAPE seasonal naive (%) | AJ38: 6.3826
AI39: Python coefficient: intercept | AJ39: 638376.76
AI40: Python coefficient: trend per month | AJ40: 423.153
AI41: Python coefficient: month 02 vs Jan | AJ41: -118907.21
...
